Workbook

Sheet 1_Exec_Summary_KPIs
A1: DECCANWINGS REGIONAL AIRLINE — FY25 ATF PRICE SHOCK & TURNAROUND MODEL
A2: CFA Club IIT Indore Induction (PS1: Consulting & Product Management) | Public Benchmarks: DGCA, IOCL, IndiGo, SpiceJet, MoCA UDAN
A4: 1. MACROECONOMIC, FUEL & FLEET OPERATING ASSUMPTIONS (PUBLIC BENCHMARKS)
A5: Parameter Code | B5: Operating / Macro Parameter | C5: Baseline (Pre-Shock) | D5: FY25 Shock / Target | E5: Units | F5: Benchmark Source & Grounded Reference
A6: ATF_BASE | B6: Domestic Metro ATF Price (Pre-Shock Baseline) | C6: 86000 | D6: 104927 | E6: INR / kl | F6: =HYPERLINK("https://iocl.com/aviation-fuel", "IOCL Aviation Fuel Archive (Delhi Metro Peak INR 1,04,927/kl)") -> IOCL Aviation Fuel Archive (Delhi Metro Peak INR 1,04,927/kl)
A7: ATF_LITRE | B7: Effective ATF Price per Litre (Delivered Into-Plane) | C7: =C6/1000 -> 86 | D7: =D6/1000 -> 104.927 | E7: INR / Litre | F7: =HYPERLINK("https://iocl.com/prices-of-petroleum-products", "IOCL Domestic Aviation Turbine Fuel Price Table") -> IOCL Domestic Aviation Turbine Fuel Price Table
A8: ATF_UDAN | B8: Concessional ATF Price under RCS-UDAN (1% State VAT) | C8: 73100 | D8: 89188 | E8: INR / kl | F8: =HYPERLINK("https://www.civilaviation.gov.in/sites/default/files/2025-09/modified-udan-scheme-v1.2-workshop-1.pdf", "MoCA Modified UDAN Scheme v1.2 (1-2% VAT Concession)") -> MoCA Modified UDAN Scheme v1.2 (1-2% VAT Concession)
A9: SEATS_A320 | B9: Narrow-Body Jet Capacity (Airbus A320ceo Standard) | C9: 180 | D9: 180 | E9: Seats | F9: =HYPERLINK("https://www.goindigo.in/press-releases/indigo-releases-q1-financial-results-of-fy-2025.html", "IndiGo / SpiceJet Narrow-Body Fleet Benchmark") -> IndiGo / SpiceJet Narrow-Body Fleet Benchmark
A10: SEATS_ATR | B10: Regional Turboprop Capacity (ATR 72-600 Standard) | C10: 78 | D10: 78 | E10: Seats | F10: =HYPERLINK("https://nsearchives.nseindia.com/annual_reports/AR_27116_INDIGO_2024_2025_A_26072025103933.pdf", "IndiGo Regional ATR 72-600 Fleet Config (78 Seats)") -> IndiGo Regional ATR 72-600 Fleet Config (78 Seats)
A11: CASK_INDIGO | B11: Benchmark Leader Total CASK (IndiGo FY25 Official) | C11: 4.62 | D11: 4.83 | E11: INR / ASK | F11: =HYPERLINK("https://www.plindia.com/ResReport/INDIGO-22-5-25-PL.pdf", "IndiGo Q1/Q3 FY25 Results (Fuel CASK INR 1.76, Ex-Fuel 2.86)") -> IndiGo Q1/Q3 FY25 Results (Fuel CASK INR 1.76, Ex-Fuel 2.86)
A12: CASK_SPICE | B12: Distressed Carrier Total CASK (SpiceJet FY25 Proxy) | C12: 5.85 | D12: 6.5 | E12: INR / ASK | F12: =HYPERLINK("https://indianexpress.com/article/smart-stocks/less-than-4-market-share-40-fleet-grounded-spicejet-avoid-crash-9902137/", "SpiceJet Q3 FY25 Analysis (Fuel INR 1.88, Ex-Fuel INR 4.62)") -> SpiceJet Q3 FY25 Analysis (Fuel INR 1.88, Ex-Fuel INR 4.62)
A13: YIELD_INDIGO | B13: Benchmark Passenger Yield (IndiGo FY25 Official) | C13: 5.1 | D13: 5.24 | E13: INR / RPK | F13: =HYPERLINK("https://www.goindigo.in/press-releases/indigo-releases-q1-financial-results-of-fy-2025.html", "IndiGo Q1 FY25 RASK INR 5.40, Passenger Yield INR 5.24/RPK") -> IndiGo Q1 FY25 RASK INR 5.40, Passenger Yield INR 5.24/RPK
A14: UDAN_VGF | B14: Average RCS-UDAN Viability Gap Funding (VGF) Subsidy | C14: 4150 | D14: 4450 | E14: INR / RCS Seat | F14: =HYPERLINK("https://www.pib.gov.in/PressReleaseDetail.aspx?PRID=2125359&reg=3&lang=1", "PIB / MoCA UDAN 10-Year Disbursement (INR 4,091 Cr on 657 routes)") -> PIB / MoCA UDAN 10-Year Disbursement (INR 4,091 Cr on 657 routes)
A15: UDAN_CAP | B15: MoCA UDAN Capped Airfare (50% of Seats for ~500km) | C15: 2650 | D15: 2750 | E15: INR / Pax | F15: =HYPERLINK("https://anantamias.com/udaan/", "MoCA Regional Connectivity Scheme Airfare Cap Schedule") -> MoCA Regional Connectivity Scheme Airfare Cap Schedule
A18: 2. EXECUTIVE DIAGNOSTIC & STRATEGIC OPTIONS BRIDGE (ANNUALIZED NETWORK P&L)
A19: Scenario / Strategic Path | B19: Active Routes | C19: Annual ASK (Millions) | D19: Network Load Factor | E19: Blended RASK (INR) | F19: Blended CASK (INR) | G19: Breakeven LF (BLF) | H19: Annual EBITDAR (INR Cr) | I19: Net Operating Margin (%)
A20: 1. Pre-Shock Baseline (FY24 @ INR 86,000/kl ATF) | B20: 8 | C20: ='2_Route_PnL_and_BLF'!I13 -> 852.786 | D20: ='2_Route_PnL_and_BLF'!G13 -> 0.72249615 | E20: ='2_Route_PnL_and_BLF'!M13 -> 4.4021895 | F20: ='2_Route_PnL_and_BLF'!P13 -> 5.0486133 | G20: ='2_Route_PnL_and_BLF'!V13 -> 0.8285885 | H20: ='2_Route_PnL_and_BLF'!T13 -> -55.126111 | I20: =H20/('2_Route_PnL_and_BLF'!N13) -> -0.14684141
A21: 2. FY25 ATF Shock Status Quo (@ INR 1,04,927/kl ATF) | B21: 8 | C21: ='2_Route_PnL_and_BLF'!I13 -> 852.786 | D21: ='2_Route_PnL_and_BLF'!G13 -> 0.72249615 | E21: ='2_Route_PnL_and_BLF'!M13 -> 4.4021895 | F21: ='2_Route_PnL_and_BLF'!R13 -> 5.4127344 | G21: ='2_Route_PnL_and_BLF'!W13 -> 0.88834879 | H21: ='2_Route_PnL_and_BLF'!U13 -> -86.177849 | I21: =H21/('2_Route_PnL_and_BLF'!N13) -> -0.22955505
A22: 3. Standalone Option A (Network Pruning + Dynamic Pricing) | B22: 6 | C22: ='3_Strategic_Options_ABC'!E14 -> 602.1405 | D22: ='3_Strategic_Options_ABC'!F14 -> 0.78164866 | E22: ='3_Strategic_Options_ABC'!G14 -> 4.9934448 | F22: ='3_Strategic_Options_ABC'!H14 -> 4.9740276 | G22: ='3_Strategic_Options_ABC'!I14 -> 0.77860919 | H22: ='3_Strategic_Options_ABC'!J14 -> -3.3308102 | I22: =H22/('3_Strategic_Options_ABC'!E14*'3_Strategic_Options_ABC'!G14/10) -> -0.011077756
A23: 4. Standalone Option B (Aggressive UDAN VGF Expansion) | B23: 8 | C23: ='3_Strategic_Options_ABC'!E26 -> 852.786 | D23: ='3_Strategic_Options_ABC'!F26 -> 0.78785824 | E23: ='3_Strategic_Options_ABC'!G26 -> 4.8633652 | F23: ='3_Strategic_Options_ABC'!H26 -> 5.0642656 | G23: ='3_Strategic_Options_ABC'!I26 -> 0.82040383 | H23: ='3_Strategic_Options_ABC'!J26 -> -17.132511 | I23: =H23/('3_Strategic_Options_ABC'!E26*'3_Strategic_Options_ABC'!G26/10) -> -0.041308941
A24: 5. Standalone Option C (Fleet Turboprop Swap + Cost Reset) | B24: 8 | C24: ='3_Strategic_Options_ABC'!E38 -> 683.55594 | D24: ='3_Strategic_Options_ABC'!F38 -> 0.8206432 | E24: ='3_Strategic_Options_ABC'!G38 -> 4.9846187 | F24: ='3_Strategic_Options_ABC'!H38 -> 4.7346286 | G24: ='3_Strategic_Options_ABC'!I38 -> 0.77948606 | H24: ='3_Strategic_Options_ABC'!J38 -> 17.088221 | I24: =H24/('3_Strategic_Options_ABC'!E38*'3_Strategic_Options_ABC'!G38/10) -> 0.050152298
A25: 6. RECOMMENDED INTEGRATED PATH (Phased A -> B -> C) | B25: 6 | C25: ='3_Strategic_Options_ABC'!E50 -> 708.9687 | D25: ='3_Strategic_Options_ABC'!F50 -> 0.82909925 | E25: ='3_Strategic_Options_ABC'!G50 -> 5.2745807 | F25: ='3_Strategic_Options_ABC'!H50 -> 4.5485015 | G25: ='3_Strategic_Options_ABC'!I50 -> 0.71496853 | H25: ='3_Strategic_Options_ABC'!J50 -> 51.476738 | I25: =H25/('3_Strategic_Options_ABC'!E50*'3_Strategic_Options_ABC'!G50/10) -> 0.13765628

Sheet 2_Route_PnL_and_BLF
A1: STEP 1 DIAGNOSIS: ROUTE-LEVEL P&L, BREAKEVEN LOAD FACTOR (BLF) & LOSS ATTRIBUTION
A2: Separating Fuel-Driven Losses (+22.0% ATF Spike) from Structurally Embedded Losses (Gauge Mismatch & Sub-380km Rail Competition)
A4: Route ID | B4: Origin - Destination Pair | C4: Archetype | D4: Stage (km) | E4: Daily Flights | F4: Seats / Flight | G4: Actual LF (%) | H4: Annual Pax | I4: Annual ASK (M) | J4: Annual RPK (M) | K4: Pax Yield (INR/RPK) | L4: Ancillary (INR/Pax) | M4: Total RASK (INR) | N4: Annual Rev (INR Cr) | O4: Pre-Shock Fuel CASK | P4: Pre-Shock Total CASK | Q4: Shock Fuel CASK | R4: Shock Total CASK | S4: Ex-Fuel CASK (INR) | T4: Pre-Shock P&L (Cr) | U4: Post-Shock P&L (Cr) | V4: Pre-Shock BLF (%) | W4: Post-Shock BLF (%) | X4: Structural Loss (Cr) | Y4: Fuel-Driven Loss (Cr) | Z4: Diagnostic Classification
A5: R1 | B5: Indore - Mumbai (IDR-BOM) | C5: Cat 1: Core Feeder | D5: 510 | E5: 4 | F5: 180 | G5: 0.84 | H5: =E5*365*F5*G5 -> 220752 | I5: =E5*365*F5*D5/1000000 -> 134.028 | J5: =I5*G5 -> 112.58352 | K5: 5.45 | L5: 420 | M5: =((J5*K5)+(H5*L5/1000000))/I5 -> 5.2697647 | N5: =I5*M5/10 -> 70.629602 | O5: 1.58 | P5: =O5+S5 -> 4.68 | Q5: =O5*('1_Exec_Summary_KPIs'!$D$6/'1_Exec_Summary_KPIs'!$C$6) -> 1.9277286 | R5: =Q5+S5 -> 5.0277286 | S5: 3.1 | T5: =I5*(M5-P5)/10 -> 7.9044984 | U5: =I5*(M5-R5)/10 -> 3.2439615 | V5: =P5/(M5/G5) -> 0.74599156 | W5: =R5/(M5/G5) -> 0.80141947 | X5: =IF(T5<0, T5, 0) -> 0 | Y5: =U5-T5 -> -4.6605369 | Z5: =IF(W5>1, "EXIT: BLF > 100% (Structurally Unviable)", IF(T5<0, "RESTRUCTURE: Gauge Mismatch + Fuel Hit", "RETAIN & REPRICE: Pure Fuel Shock")) -> RETAIN & REPRICE: Pure Fuel Shock
A6: R2 | B6: Bhopal - Delhi (BHO-DEL) | C6: Cat 1: Core Feeder | D6: 600 | E6: 4 | F6: 180 | G6: 0.82 | H6: =E6*365*F6*G6 -> 215496 | I6: =E6*365*F6*D6/1000000 -> 157.68 | J6: =I6*G6 -> 129.2976 | K6: 5.3 | L6: 410 | M6: =((J6*K6)+(H6*L6/1000000))/I6 -> 4.9063333 | N6: =I6*M6/10 -> 77.363064 | O6: 1.52 | P6: =O6+S6 -> 4.5 | Q6: =O6*('1_Exec_Summary_KPIs'!$D$6/'1_Exec_Summary_KPIs'!$C$6) -> 1.8545237 | R6: =Q6+S6 -> 4.8345237 | S6: 2.98 | T6: =I6*(M6-P6)/10 -> 6.407064 | U6: =I6*(M6-R6)/10 -> 1.132294 | V6: =P6/(M6/G6) -> 0.75208914 | W6: =R6/(M6/G6) -> 0.80799839 | X6: =IF(T6<0, T6, 0) -> 0 | Y6: =U6-T6 -> -5.27477 | Z6: =IF(W6>1, "EXIT: BLF > 100% (Structurally Unviable)", IF(T6<0, "RESTRUCTURE: Gauge Mismatch + Fuel Hit", "RETAIN & REPRICE: Pure Fuel Shock")) -> RETAIN & REPRICE: Pure Fuel Shock
A7: R3 | B7: Surat - Bengaluru (STV-BLR) | C7: Cat 1: Core Feeder | D7: 640 | E7: 4 | F7: 180 | G7: 0.83 | H7: =E7*365*F7*G7 -> 218124 | I7: =E7*365*F7*D7/1000000 -> 168.192 | J7: =I7*G7 -> 139.59936 | K7: 5.2 | L7: 430 | M7: =((J7*K7)+(H7*L7/1000000))/I7 -> 4.8736562 | N7: =I7*M7/10 -> 81.970999 | O7: 1.49 | P7: =O7+S7 -> 4.41 | Q7: =O7*('1_Exec_Summary_KPIs'!$D$6/'1_Exec_Summary_KPIs'!$C$6) -> 1.8179213 | R7: =Q7+S7 -> 4.7379213 | S7: 2.92 | T7: =I7*(M7-P7)/10 -> 7.7983272 | U7: =I7*(M7-R7)/10 -> 2.2829536 | V7: =P7/(M7/G7) -> 0.75103779 | W7: =R7/(M7/G7) -> 0.80688388 | X7: =IF(T7<0, T7, 0) -> 0 | Y7: =U7-T7 -> -5.5153736 | Z7: =IF(W7>1, "EXIT: BLF > 100% (Structurally Unviable)", IF(T7<0, "RESTRUCTURE: Gauge Mismatch + Fuel Hit", "RETAIN & REPRICE: Pure Fuel Shock")) -> RETAIN & REPRICE: Pure Fuel Shock
A8: R4 | B8: Belagavi - Mumbai (IXG-BOM) | C8: Cat 2: Gauge Mismatch | D8: 410 | E8: 2 | F8: 180 | G8: 0.62 | H8: =E8*365*F8*G8 -> 81468 | I8: =E8*365*F8*D8/1000000 -> 53.874 | J8: =I8*G8 -> 33.40188 | K8: 5.85 | L8: 380 | M8: =((J8*K8)+(H8*L8/1000000))/I8 -> 4.2016341 | N8: =I8*M8/10 -> 22.635884 | O8: 1.76 | P8: =O8+S8 -> 5.41 | Q8: =O8*('1_Exec_Summary_KPIs'!$D$6/'1_Exec_Summary_KPIs'!$C$6) -> 2.1473433 | R8: =Q8+S8 -> 5.7973433 | S8: 3.65 | T8: =I8*(M8-P8)/10 -> -6.5099502 | U8: =I8*(M8-R8)/10 -> -8.5967233 | V8: =P8/(M8/G8) -> 0.79830844 | W8: =R8/(M8/G8) -> 0.85546544 | X8: =IF(T8<0, T8, 0) -> -6.5099502 | Y8: =U8-T8 -> -2.0867731 | Z8: =IF(W8>1, "EXIT: BLF > 100% (Structurally Unviable)", IF(T8<0, "RESTRUCTURE: Gauge Mismatch + Fuel Hit", "RETAIN & REPRICE: Pure Fuel Shock")) -> RESTRUCTURE: Gauge Mismatch + Fuel Hit
A9: R5 | B9: Jabalpur - Delhi (JLR-DEL) | C9: Cat 2: Gauge Mismatch | D9: 540 | E9: 2 | F9: 180 | G9: 0.6 | H9: =E9*365*F9*G9 -> 78840 | I9: =E9*365*F9*D9/1000000 -> 70.956 | J9: =I9*G9 -> 42.5736 | K9: 5.65 | L9: 390 | M9: =((J9*K9)+(H9*L9/1000000))/I9 -> 3.8233333 | N9: =I9*M9/10 -> 27.128844 | O9: 1.66 | P9: =O9+S9 -> 5.08 | Q9: =O9*('1_Exec_Summary_KPIs'!$D$6/'1_Exec_Summary_KPIs'!$C$6) -> 2.0253351 | R9: =Q9+S9 -> 5.4453351 | S9: 3.42 | T9: =I9*(M9-P9)/10 -> -8.916804 | U9: =I9*(M9-R9)/10 -> -11.509076 | V9: =P9/(M9/G9) -> 0.79721011 | W9: =R9/(M9/G9) -> 0.85454256 | X9: =IF(T9<0, T9, 0) -> -8.916804 | Y9: =U9-T9 -> -2.5922719 | Z9: =IF(W9>1, "EXIT: BLF > 100% (Structurally Unviable)", IF(T9<0, "RESTRUCTURE: Gauge Mismatch + Fuel Hit", "RETAIN & REPRICE: Pure Fuel Shock")) -> RESTRUCTURE: Gauge Mismatch + Fuel Hit
A10: R6 | B10: Gorakhpur - Mumbai (GOP-BOM) | C10: Cat 2: Gauge Mismatch | D10: 620 | E10: 2 | F10: 180 | G10: 0.64 | H10: =E10*365*F10*G10 -> 84096 | I10: =E10*365*F10*D10/1000000 -> 81.468 | J10: =I10*G10 -> 52.13952 | K10: 5.4 | L10: 400 | M10: =((J10*K10)+(H10*L10/1000000))/I10 -> 3.8689032 | N10: =I10*M10/10 -> 31.519181 | O10: 1.56 | P10: =O10+S10 -> 4.86 | Q10: =O10*('1_Exec_Summary_KPIs'!$D$6/'1_Exec_Summary_KPIs'!$C$6) -> 1.903327 | R10: =Q10+S10 -> 5.203327 | S10: 3.3 | T10: =I10*(M10-P10)/10 -> -8.0742672 | U10: =I10*(M10-R10)/10 -> -10.871283 | V10: =P10/(M10/G10) -> 0.80394877 | W10: =R10/(M10/G10) -> 0.86074246 | X10: =IF(T10<0, T10, 0) -> -8.0742672 | Y10: =U10-T10 -> -2.7970162 | Z10: =IF(W10>1, "EXIT: BLF > 100% (Structurally Unviable)", IF(T10<0, "RESTRUCTURE: Gauge Mismatch + Fuel Hit", "RETAIN & REPRICE: Pure Fuel Shock")) -> RESTRUCTURE: Gauge Mismatch + Fuel Hit
A11: R7 | B11: Nashik - Mumbai (ISK-BOM) | C11: Cat 3: Unviable Short | D11: 320 | E11: 4 | F11: 180 | G11: 0.56 | H11: =E11*365*F11*G11 -> 147168 | I11: =E11*365*F11*D11/1000000 -> 84.096 | J11: =I11*G11 -> 47.09376 | K11: 5.15 | L11: 320 | M11: =((J11*K11)+(H11*L11/1000000))/I11 -> 3.444 | N11: =I11*M11/10 -> 28.962662 | O11: 2.05 | P11: =O11+S11 -> 6.5 | Q11: =O11*('1_Exec_Summary_KPIs'!$D$6/'1_Exec_Summary_KPIs'!$C$6) -> 2.5011669 | R11: =Q11+S11 -> 6.9511669 | S11: 4.45 | T11: =I11*(M11-P11)/10 -> -25.699738 | U11: =I11*(M11-R11)/10 -> -29.49387 | V11: =P11/(M11/G11) -> 1.0569106 | W11: =R11/(M11/G11) -> 1.130271 | X11: =IF(T11<0, T11, 0) -> -25.699738 | Y11: =U11-T11 -> -3.7941328 | Z11: =IF(W11>1, "EXIT: BLF > 100% (Structurally Unviable)", IF(T11<0, "RESTRUCTURE: Gauge Mismatch + Fuel Hit", "RETAIN & REPRICE: Pure Fuel Shock")) -> EXIT: BLF > 100% (Structurally Unviable)
A12: R8 | B12: Kanpur - Delhi (KNU-DEL) | C12: Cat 3: Unviable Short | D12: 390 | E12: 4 | F12: 180 | G12: 0.58 | H12: =E12*365*F12*G12 -> 152424 | I12: =E12*365*F12*D12/1000000 -> 102.492 | J12: =I12*G12 -> 59.44536 | K12: 5.05 | L12: 340 | M12: =((J12*K12)+(H12*L12/1000000))/I12 -> 3.434641 | N12: =I12*M12/10 -> 35.202323 | O12: 1.92 | P12: =O12+S12 -> 6.17 | Q12: =O12*('1_Exec_Summary_KPIs'!$D$6/'1_Exec_Summary_KPIs'!$C$6) -> 2.3425563 | R12: =Q12+S12 -> 6.5925563 | S12: 4.25 | T12: =I12*(M12-P12)/10 -> -28.035241 | U12: =I12*(M12-R12)/10 -> -32.366105 | V12: =P12/(M12/G12) -> 1.0419138 | W12: =R12/(M12/G12) -> 1.11327 | X12: =IF(T12<0, T12, 0) -> -28.035241 | Y12: =U12-T12 -> -4.3308638 | Z12: =IF(W12>1, "EXIT: BLF > 100% (Structurally Unviable)", IF(T12<0, "RESTRUCTURE: Gauge Mismatch + Fuel Hit", "RETAIN & REPRICE: Pure Fuel Shock")) -> EXIT: BLF > 100% (Structurally Unviable)
A13: TOTAL | B13: Network Total / Weighted Average | C13: 8 Active Routes | D13: =AVERAGE(D5:D12) -> 503.75 | E13: =SUM(E5:E12) -> 26 | F13: =AVERAGE(F5:F12) -> 180 | G13: =J13/I13 -> 0.72249615 | H13: =SUM(H5:H12) -> 1198368 | I13: =SUM(I5:I12) -> 852.786 | J13: =SUM(J5:J12) -> 616.1346 | K13: =SUMPRODUCT(J5:J12,K5:K12)/J13 -> 5.3316293 | L13: =SUMPRODUCT(H5:H12,L5:L12)/H13 -> 391.4693 | M13: =N13*10/I13 -> 4.4021895 | N13: =SUM(N5:N12) -> 375.41256 | O13: =SUMPRODUCT(I5:I12,O5:O12)/I13 -> 1.6544838 | P13: =SUMPRODUCT(I5:I12,P5:P12)/I13 -> 5.0486133 | Q13: =SUMPRODUCT(I5:I12,Q5:Q12)/I13 -> 2.0186049 | R13: =SUMPRODUCT(I5:I12,R5:R12)/I13 -> 5.4127344 | S13: =SUMPRODUCT(I5:I12,S5:S12)/I13 -> 3.3941294 | T13: =SUM(T5:T12) -> -55.126111 | U13: =SUM(U5:U12) -> -86.177849 | V13: =P13/(M13/G13) -> 0.8285885 | W13: =R13/(M13/G13) -> 0.88834879 | X13: =SUM(X5:X12) -> -77.236 | Y13: =SUM(Y5:Y12) -> -31.051738 | Z13: Net P&L Decomposition Complete

Sheet 3_Strategic_Options_ABC
A1: STEP 2 & STEP 3: QUANTITATIVE MODELING OF STRATEGIC OPTIONS A, B, C & INTEGRATED ROADMAP
A2: Comparing Option A (Network Optimization & Elasticity), Option B (UDAN VGF & Fare Caps), Option C (ATR 72-600 Fleet Swap), and Recommended Hybrid Path
A4: OPTION A: NETWORK OPTIMIZATION & DYNAMIC PRICING (PRUNE R7-R8 + YIELD MANAGEMENT)
A5: Route ID | B5: Route Name | C5: Action / Strategic Lever Applied | D5: Daily Flts & Gauge | E5: Annual ASK (M) | F5: Modeled LF (%) | G5: Modeled RASK (INR) | H5: Modeled CASK (INR) | I5: Modeled BLF (%) | J5: Annual EBITDAR (INR Cr) | K5: Variance vs. Shock (INR Cr)
A6: R1 | B6: Indore - Mumbai | C6: Dynamic Peak Pricing (+8% Yield, e = -0.42) | D6: 4x A320 (180s) | E6: ='2_Route_PnL_and_BLF'!I5 -> 134.028 | F6: 0.815 | G6: ='2_Route_PnL_and_BLF'!M5*1.048 -> 5.5227134 | H6: ='2_Route_PnL_and_BLF'!R5*0.99 -> 4.9774513 | I6: =H6/(G6/F6) -> 0.73453437 | J6: =E6*(G6-H6)/10 -> 7.3080388 | K6: =J6-'2_Route_PnL_and_BLF'!U5 -> 4.0640773
A7: R2 | B7: Bhopal - Delhi | C7: Dynamic Peak Pricing (+7.5% Yield, e = -0.45) | D7: 4x A320 (180s) | E7: ='2_Route_PnL_and_BLF'!I6 -> 157.68 | F7: 0.795 | G7: ='2_Route_PnL_and_BLF'!M6*1.044 -> 5.122212 | H7: ='2_Route_PnL_and_BLF'!R6*0.99 -> 4.7861785 | I7: =H7/(G7/F7) -> 0.74284545 | J7: =E7*(G7-H7)/10 -> 5.2985765 | K7: =J7-'2_Route_PnL_and_BLF'!U6 -> 4.1662825
A8: R3 | B8: Surat - Bengaluru | C8: Dynamic Peak Pricing (+7.5% Yield, e = -0.45) | D8: 4x A320 (180s) | E8: ='2_Route_PnL_and_BLF'!I7 -> 168.192 | F8: 0.805 | G8: ='2_Route_PnL_and_BLF'!M7*1.045 -> 5.0929708 | H8: ='2_Route_PnL_and_BLF'!R7*0.99 -> 4.6905421 | I8: =H8/(G8/F8) -> 0.74139172 | J8: =E8*(G8-H8)/10 -> 6.768529 | K8: =J8-'2_Route_PnL_and_BLF'!U7 -> 4.4855754
A9: R4 | B9: Belagavi - Mumbai | C9: Consolidate Frequency & Advance Purchase Tiers | D9: 1x A320 (180s) | E9: ='2_Route_PnL_and_BLF'!I8*0.65 -> 35.0181 | F9: 0.71 | G9: ='2_Route_PnL_and_BLF'!M8*1.08 -> 4.5377649 | H9: ='2_Route_PnL_and_BLF'!R8*1.02 -> 5.9132901 | I9: =H9/(G9/F9) -> 0.92522114 | J9: =E9*(G9-H9)/10 -> -4.8168281 | K9: =J9-'2_Route_PnL_and_BLF'!U8 -> 3.7798952
A10: R5 | B10: Jabalpur - Delhi | C10: Consolidate Frequency & Advance Purchase Tiers | D10: 1x A320 (180s) | E10: ='2_Route_PnL_and_BLF'!I9*0.65 -> 46.1214 | F10: 0.69 | G10: ='2_Route_PnL_and_BLF'!M9*1.08 -> 4.1292 | H10: ='2_Route_PnL_and_BLF'!R9*1.02 -> 5.5542418 | I10: =H10/(G10/F10) -> 0.92812817 | J10: =E10*(G10-H10)/10 -> -6.5724924 | K10: =J10-'2_Route_PnL_and_BLF'!U9 -> 4.9365835
A11: R6 | B11: Gorakhpur - Mumbai | C11: Consolidate Frequency & Off-Peak Stimulative Fare | D11: 1x A320 (180s) | E11: ='2_Route_PnL_and_BLF'!I10*0.75 -> 61.101 | F11: 0.72 | G11: ='2_Route_PnL_and_BLF'!M10*1.07 -> 4.1397265 | H11: ='2_Route_PnL_and_BLF'!R10*1.01 -> 5.2553602 | I11: =H11/(G11/F11) -> 0.91403609 | J11: =E11*(G11-H11)/10 -> -6.8166341 | K11: =J11-'2_Route_PnL_and_BLF'!U10 -> 4.0546494
A12: R7 | B12: Nashik - Mumbai | C12: IMMEDIATE ROUTE EXIT (Avoidable Cash Burn Cut) | D12: 0x (Exited) | E12: 0 | F12: 0 | G12: 0 | H12: 0 | I12: 0 | J12: -2.1 | K12: =J12-'2_Route_PnL_and_BLF'!U11 -> 27.39387
A13: R8 | B13: Kanpur - Delhi | C13: IMMEDIATE ROUTE EXIT (Avoidable Cash Burn Cut) | D13: 0x (Exited) | E13: 0 | F13: 0 | G13: 0 | H13: 0 | I13: 0 | J13: -2.4 | K13: =J13-'2_Route_PnL_and_BLF'!U12 -> 29.966105
A14: TOTAL | B14: Option Network Total / Weighted Average | C14: Consolidated Impact | D14: - | E14: =SUM(E6:E13) -> 602.1405 | F14: =SUMPRODUCT(E6:E13,F6:F13)/E14 -> 0.78164866 | G14: =SUMPRODUCT(E6:E13,G6:G13)/E14 -> 4.9934448 | H14: =SUMPRODUCT(E6:E13,H6:H13)/E14 -> 4.9740276 | I14: =H14/(G14/F14) -> 0.77860919 | J14: =SUM(J6:J13) -> -3.3308102 | K14: =SUM(K6:K13) -> 82.847039
A16: OPTION B: GOVERNMENT-BACKED UDAN EXPANSION ON ALL TIER-3 ROUTES (A320 GAUGE RETAINED)
A17: Route ID | B17: Route Name | C17: Action / Strategic Lever Applied | D17: Daily Flts & Gauge | E17: Annual ASK (M) | F17: Modeled LF (%) | G17: Modeled RASK (INR) | H17: Modeled CASK (INR) | I17: Modeled BLF (%) | J17: Annual EBITDAR (INR Cr) | K17: Variance vs. Shock (INR Cr)
A18: R1 | B18: Indore - Mumbai | C18: Non-RCS Commercial Trunk (Unchanged) | D18: 4x A320 (180s) | E18: ='2_Route_PnL_and_BLF'!I5 -> 134.028 | F18: 0.84 | G18: ='2_Route_PnL_and_BLF'!M5 -> 5.2697647 | H18: ='2_Route_PnL_and_BLF'!R5 -> 5.0277286 | I18: =H18/(G18/F18) -> 0.80141947 | J18: =E18*(G18-H18)/10 -> 3.2439615 | K18: =J18-'2_Route_PnL_and_BLF'!U5 -> 0
A19: R2 | B19: Bhopal - Delhi | C19: Non-RCS Commercial Trunk (Unchanged) | D19: 4x A320 (180s) | E19: ='2_Route_PnL_and_BLF'!I6 -> 157.68 | F19: 0.82 | G19: ='2_Route_PnL_and_BLF'!M6 -> 4.9063333 | H19: ='2_Route_PnL_and_BLF'!R6 -> 4.8345237 | I19: =H19/(G19/F19) -> 0.80799839 | J19: =E19*(G19-H19)/10 -> 1.132294 | K19: =J19-'2_Route_PnL_and_BLF'!U6 -> 0
A20: R3 | B20: Surat - Bengaluru | C20: Non-RCS Commercial Trunk (Unchanged) | D20: 4x A320 (180s) | E20: ='2_Route_PnL_and_BLF'!I7 -> 168.192 | F20: 0.83 | G20: ='2_Route_PnL_and_BLF'!M7 -> 4.8736562 | H20: ='2_Route_PnL_and_BLF'!R7 -> 4.7379213 | I20: =H20/(G20/F20) -> 0.80688388 | J20: =E20*(G20-H20)/10 -> 2.2829536 | K20: =J20-'2_Route_PnL_and_BLF'!U7 -> 0
A21: R4 | B21: Belagavi - Mumbai | C21: UDAN RCS Conversion (VGF + 1% VAT, 40-Seat Cap) | D21: 2x A320 (180s) | E21: ='2_Route_PnL_and_BLF'!I8 -> 53.874 | F21: 0.76 | G21: 4.98 | H21: ='2_Route_PnL_and_BLF'!R8*0.87 -> 5.0436886 | I21: =H21/(G21/F21) -> 0.76971955 | J21: =E21*(G21-H21)/10 -> -0.34311614 | K21: =J21-'2_Route_PnL_and_BLF'!U8 -> 8.2536071
A22: R5 | B22: Jabalpur - Delhi | C22: UDAN RCS Conversion (VGF + 1% VAT, 40-Seat Cap) | D22: 2x A320 (180s) | E22: ='2_Route_PnL_and_BLF'!I9 -> 70.956 | F22: 0.75 | G22: 4.76 | H22: ='2_Route_PnL_and_BLF'!R9*0.87 -> 4.7374416 | I22: =H22/(G22/F22) -> 0.74644562 | J22: =E22*(G22-H22)/10 -> 0.16006573 | K22: =J22-'2_Route_PnL_and_BLF'!U9 -> 11.669142
A23: R6 | B23: Gorakhpur - Mumbai | C23: UDAN RCS Conversion (VGF + 1% VAT, 40-Seat Cap) | D23: 2x A320 (180s) | E23: ='2_Route_PnL_and_BLF'!I10 -> 81.468 | F23: 0.77 | G23: 4.68 | H23: ='2_Route_PnL_and_BLF'!R10*0.87 -> 4.5268945 | I23: =H23/(G23/F23) -> 0.74480956 | J23: =E23*(G23-H23)/10 -> 1.2473201 | K23: =J23-'2_Route_PnL_and_BLF'!U10 -> 12.118604
A24: R7 | B24: Nashik - Mumbai | C24: UDAN RCS Conversion (140 Unsubsidized A320 Seats Bleed) | D24: 4x A320 (180s) | E24: ='2_Route_PnL_and_BLF'!I11 -> 84.096 | F24: 0.71 | G24: 4.65 | H24: ='2_Route_PnL_and_BLF'!R11*0.88 -> 6.1170268 | I24: =H24/(G24/F24) -> 0.93399765 | J24: =E24*(G24-H24)/10 -> -12.337109 | K24: =J24-'2_Route_PnL_and_BLF'!U11 -> 17.156762
A25: R8 | B25: Kanpur - Delhi | C25: UDAN RCS Conversion (140 Unsubsidized A320 Seats Bleed) | D25: 4x A320 (180s) | E25: ='2_Route_PnL_and_BLF'!I12 -> 102.492 | F25: 0.72 | G25: 4.58 | H25: ='2_Route_PnL_and_BLF'!R12*0.88 -> 5.8014495 | I25: =H25/(G25/F25) -> 0.91201827 | J25: =E25*(G25-H25)/10 -> -12.51888 | K25: =J25-'2_Route_PnL_and_BLF'!U12 -> 19.847225
A26: TOTAL | B26: Option Network Total / Weighted Average | C26: Consolidated Impact | D26: - | E26: =SUM(E18:E25) -> 852.786 | F26: =SUMPRODUCT(E18:E25,F18:F25)/E26 -> 0.78785824 | G26: =SUMPRODUCT(E18:E25,G18:G25)/E26 -> 4.8633652 | H26: =SUMPRODUCT(E18:E25,H18:H25)/E26 -> 5.0642656 | I26: =H26/(G26/F26) -> 0.82040383 | J26: =SUM(J18:J25) -> -17.132511 | K26: =SUM(K18:K25) -> 69.045338
A28: OPTION C: STRUCTURAL OPERATING MODEL REDESIGN (ATR 72-600 TURBOPROP SWAP + COST RESET)
A29: Route ID | B29: Route Name | C29: Action / Strategic Lever Applied | D29: Daily Flts & Gauge | E29: Annual ASK (M) | F29: Modeled LF (%) | G29: Modeled RASK (INR) | H29: Modeled CASK (INR) | I29: Modeled BLF (%) | J29: Annual EBITDAR (INR Cr) | K29: Variance vs. Shock (INR Cr)
A30: R1 | B30: Indore - Mumbai | C30: A320 Retained + PBH Maintenance & Fuel Tankering (-4% CASK) | D30: 4x A320 (180s) | E30: ='2_Route_PnL_and_BLF'!I5 -> 134.028 | F30: 0.84 | G30: ='2_Route_PnL_and_BLF'!M5 -> 5.2697647 | H30: ='2_Route_PnL_and_BLF'!R5*0.955 -> 4.8014808 | I30: =H30/(G30/F30) -> 0.76535559 | J30: =E30*(G30-H30)/10 -> 6.2763153 | K30: =J30-'2_Route_PnL_and_BLF'!U5 -> 3.0323538
A31: R2 | B31: Bhopal - Delhi | C31: A320 Retained + PBH Maintenance & Fuel Tankering (-4% CASK) | D31: 4x A320 (180s) | E31: ='2_Route_PnL_and_BLF'!I6 -> 157.68 | F31: 0.82 | G31: ='2_Route_PnL_and_BLF'!M6 -> 4.9063333 | H31: ='2_Route_PnL_and_BLF'!R6*0.955 -> 4.6169702 | I31: =H31/(G31/F31) -> 0.77163847 | J31: =E31*(G31-H31)/10 -> 4.5626786 | K31: =J31-'2_Route_PnL_and_BLF'!U6 -> 3.4303847
A32: R3 | B32: Surat - Bengaluru | C32: A320 Retained + PBH Maintenance & Fuel Tankering (-4% CASK) | D32: 4x A320 (180s) | E32: ='2_Route_PnL_and_BLF'!I7 -> 168.192 | F32: 0.83 | G32: ='2_Route_PnL_and_BLF'!M7 -> 4.8736562 | H32: ='2_Route_PnL_and_BLF'!R7*0.955 -> 4.5247148 | I32: =H32/(G32/F32) -> 0.7705741 | J32: =E32*(G32-H32)/10 -> 5.8689157 | K32: =J32-'2_Route_PnL_and_BLF'!U7 -> 3.5859621
A33: R4 | B33: Belagavi - Mumbai | C33: Fleet Right-Sizing to ATR 72-600 (78s) -> LF Jumps to 84% | D33: 3x ATR72 (78s) | E33: ='2_Route_PnL_and_BLF'!I8*0.65 -> 35.0181 | F33: 0.84 | G33: 5.55 | H33: 5.02 | I33: =H33/(G33/F33) -> 0.75978378 | J33: =E33*(G33-H33)/10 -> 1.8559593 | K33: =J33-'2_Route_PnL_and_BLF'!U8 -> 10.452683
A34: R5 | B34: Jabalpur - Delhi | C34: Fleet Right-Sizing to ATR 72-600 (78s) -> LF Jumps to 83% | D34: 3x ATR72 (78s) | E34: ='2_Route_PnL_and_BLF'!I9*0.65 -> 46.1214 | F34: 0.83 | G34: 5.38 | H34: 4.86 | I34: =H34/(G34/F34) -> 0.74977695 | J34: =E34*(G34-H34)/10 -> 2.3983128 | K34: =J34-'2_Route_PnL_and_BLF'!U9 -> 13.907389
A35: R6 | B35: Gorakhpur - Mumbai | C35: Fleet Right-Sizing to ATR 72-600 (78s) -> LF Jumps to 85% | D35: 3x ATR72 (78s) | E35: ='2_Route_PnL_and_BLF'!I10*0.65 -> 52.9542 | F35: 0.85 | G35: 5.25 | H35: 4.74 | I35: =H35/(G35/F35) -> 0.76742857 | J35: =E35*(G35-H35)/10 -> 2.7006642 | K35: =J35-'2_Route_PnL_and_BLF'!U10 -> 13.571948
A36: R7 | B36: Nashik - Mumbai | C36: ATR 72-600 Swap (Still Sub-Scale vs. Rail Competition) | D36: 3x ATR72 (78s) | E36: ='2_Route_PnL_and_BLF'!I11*0.48 -> 40.36608 | F36: 0.74 | G36: 4.35 | H36: 5.15 | I36: =H36/(G36/F36) -> 0.87609195 | J36: =E36*(G36-H36)/10 -> -3.2292864 | K36: =J36-'2_Route_PnL_and_BLF'!U11 -> 26.264584
A37: R8 | B37: Kanpur - Delhi | C37: ATR 72-600 Swap (Still Sub-Scale vs. Vande Bharat Rail) | D37: 3x ATR72 (78s) | E37: ='2_Route_PnL_and_BLF'!I12*0.48 -> 49.19616 | F37: 0.75 | G37: 4.3 | H37: 4.98 | I37: =H37/(G37/F37) -> 0.86860465 | J37: =E37*(G37-H37)/10 -> -3.3453389 | K37: =J37-'2_Route_PnL_and_BLF'!U12 -> 29.020766
A38: TOTAL | B38: Option Network Total / Weighted Average | C38: Consolidated Impact | D38: - | E38: =SUM(E30:E37) -> 683.55594 | F38: =SUMPRODUCT(E30:E37,F30:F37)/E38 -> 0.8206432 | G38: =SUMPRODUCT(E30:E37,G30:G37)/E38 -> 4.9846187 | H38: =SUMPRODUCT(E30:E37,H30:H37)/E38 -> 4.7346286 | I38: =H38/(G38/F38) -> 0.77948606 | J38: =SUM(J30:J37) -> 17.088221 | K38: =SUM(K30:K37) -> 103.26607
A40: RECOMMENDED INTEGRATED PATH: PHASED A (PRUNE & REPRICE) + B (SELECTIVE UDAN) + C (ATR72 GAUGE SWAP)
A41: Route ID | B41: Route Name | C41: Action / Strategic Lever Applied | D41: Daily Flts & Gauge | E41: Annual ASK (M) | F41: Modeled LF (%) | G41: Modeled RASK (INR) | H41: Modeled CASK (INR) | I41: Modeled BLF (%) | J41: Annual EBITDAR (INR Cr) | K41: Variance vs. Shock (INR Cr)
A42: R1 | B42: Indore - Mumbai | C42: Core Trunk + Slot Redeployment (5x A320 + Dynamic Pricing + PBH) | D42: 5x A320 (180s) | E42: ='2_Route_PnL_and_BLF'!I5*1.25 -> 167.535 | F42: 0.825 | G42: 5.38 | H42: 4.74 | I42: =H42/(G42/F42) -> 0.72685874 | J42: =E42*(G42-H42)/10 -> 10.72224 | K42: =J42-'2_Route_PnL_and_BLF'!U5 -> 7.4782785
A43: R2 | B43: Bhopal - Delhi | C43: Core Trunk + Slot Redeployment (5x A320 + Dynamic Pricing + PBH) | D43: 5x A320 (180s) | E43: ='2_Route_PnL_and_BLF'!I6*1.25 -> 197.1 | F43: 0.81 | G43: 5.16 | H43: 4.56 | I43: =H43/(G43/F43) -> 0.71581395 | J43: =E43*(G43-H43)/10 -> 11.826 | K43: =J43-'2_Route_PnL_and_BLF'!U6 -> 10.693706
A44: R3 | B44: Surat - Bengaluru | C44: Core Trunk + Slot Redeployment (5x A320 + Dynamic Pricing + PBH) | D44: 5x A320 (180s) | E44: ='2_Route_PnL_and_BLF'!I7*1.25 -> 210.24 | F44: 0.82 | G44: 5.14 | H44: 4.48 | I44: =H44/(G44/F44) -> 0.71470817 | J44: =E44*(G44-H44)/10 -> 13.87584 | K44: =J44-'2_Route_PnL_and_BLF'!U7 -> 11.592886
...

Sheet 4_Risk_Sensitivity_Matrix
A1: STEP 4: TWO-WAY SENSITIVITY MATRIX & STRESS SCENARIO MODELING
A2: Modeling Network EBITDAR (INR Cr) across ATF Fuel Price Shocks (INR/kl) vs. Passenger Yield / Load Factor Realization
A4: 1. TWO-WAY SENSITIVITY: RECOMMENDED STRATEGY ANNUAL EBITDAR (INR CR) — ATF PRICE vs. YIELD SHIFT
A5: ATF Price (INR/kl) \ Yield Shift | B5: -0.06 | C5: -0.03 | D5: 0 | E5: 0.03 | F5: 0.06
A6: 85000 | B6: ='3_Strategic_Options_ABC'!$E$50*(('3_Strategic_Options_ABC'!$G$50*(1+B$5))-('3_Strategic_Options_ABC'!$H$50*0.65 + '3_Strategic_Options_ABC'!$H$50*0.35*($A6/104927)))/10 -> 50.474398 | C6: ='3_Strategic_Options_ABC'!$E$50*(('3_Strategic_Options_ABC'!$G$50*(1+C$5))-('3_Strategic_Options_ABC'!$H$50*0.65 + '3_Strategic_Options_ABC'!$H$50*0.35*($A6/104927)))/10 -> 61.692935 | D6: ='3_Strategic_Options_ABC'!$E$50*(('3_Strategic_Options_ABC'!$G$50*(1+D$5))-('3_Strategic_Options_ABC'!$H$50*0.65 + '3_Strategic_Options_ABC'!$H$50*0.35*($A6/104927)))/10 -> 72.911473 | E6: ='3_Strategic_Options_ABC'!$E$50*(('3_Strategic_Options_ABC'!$G$50*(1+E$5))-('3_Strategic_Options_ABC'!$H$50*0.65 + '3_Strategic_Options_ABC'!$H$50*0.35*($A6/104927)))/10 -> 84.130011 | F6: ='3_Strategic_Options_ABC'!$E$50*(('3_Strategic_Options_ABC'!$G$50*(1+F$5))-('3_Strategic_Options_ABC'!$H$50*0.65 + '3_Strategic_Options_ABC'!$H$50*0.35*($A6/104927)))/10 -> 95.348549
A7: 95000 | B7: ='3_Strategic_Options_ABC'!$E$50*(('3_Strategic_Options_ABC'!$G$50*(1+B$5))-('3_Strategic_Options_ABC'!$H$50*0.65 + '3_Strategic_Options_ABC'!$H$50*0.35*($A7/104927)))/10 -> 39.717769 | C7: ='3_Strategic_Options_ABC'!$E$50*(('3_Strategic_Options_ABC'!$G$50*(1+C$5))-('3_Strategic_Options_ABC'!$H$50*0.65 + '3_Strategic_Options_ABC'!$H$50*0.35*($A7/104927)))/10 -> 50.936306 | D7: ='3_Strategic_Options_ABC'!$E$50*(('3_Strategic_Options_ABC'!$G$50*(1+D$5))-('3_Strategic_Options_ABC'!$H$50*0.65 + '3_Strategic_Options_ABC'!$H$50*0.35*($A7/104927)))/10 -> 62.154844 | E7: ='3_Strategic_Options_ABC'!$E$50*(('3_Strategic_Options_ABC'!$G$50*(1+E$5))-('3_Strategic_Options_ABC'!$H$50*0.65 + '3_Strategic_Options_ABC'!$H$50*0.35*($A7/104927)))/10 -> 73.373382 | F7: ='3_Strategic_Options_ABC'!$E$50*(('3_Strategic_Options_ABC'!$G$50*(1+F$5))-('3_Strategic_Options_ABC'!$H$50*0.65 + '3_Strategic_Options_ABC'!$H$50*0.35*($A7/104927)))/10 -> 84.59192
A8: 104927 | B8: ='3_Strategic_Options_ABC'!$E$50*(('3_Strategic_Options_ABC'!$G$50*(1+B$5))-('3_Strategic_Options_ABC'!$H$50*0.65 + '3_Strategic_Options_ABC'!$H$50*0.35*($A8/104927)))/10 -> 29.039663 | C8: ='3_Strategic_Options_ABC'!$E$50*(('3_Strategic_Options_ABC'!$G$50*(1+C$5))-('3_Strategic_Options_ABC'!$H$50*0.65 + '3_Strategic_Options_ABC'!$H$50*0.35*($A8/104927)))/10 -> 40.258201 | D8: ='3_Strategic_Options_ABC'!$E$50*(('3_Strategic_Options_ABC'!$G$50*(1+D$5))-('3_Strategic_Options_ABC'!$H$50*0.65 + '3_Strategic_Options_ABC'!$H$50*0.35*($A8/104927)))/10 -> 51.476738 | E8: ='3_Strategic_Options_ABC'!$E$50*(('3_Strategic_Options_ABC'!$G$50*(1+E$5))-('3_Strategic_Options_ABC'!$H$50*0.65 + '3_Strategic_Options_ABC'!$H$50*0.35*($A8/104927)))/10 -> 62.695276 | F8: ='3_Strategic_Options_ABC'!$E$50*(('3_Strategic_Options_ABC'!$G$50*(1+F$5))-('3_Strategic_Options_ABC'!$H$50*0.65 + '3_Strategic_Options_ABC'!$H$50*0.35*($A8/104927)))/10 -> 73.913814
A9: 115000 | B9: ='3_Strategic_Options_ABC'!$E$50*(('3_Strategic_Options_ABC'!$G$50*(1+B$5))-('3_Strategic_Options_ABC'!$H$50*0.65 + '3_Strategic_Options_ABC'!$H$50*0.35*($A9/104927)))/10 -> 18.20451 | C9: ='3_Strategic_Options_ABC'!$E$50*(('3_Strategic_Options_ABC'!$G$50*(1+C$5))-('3_Strategic_Options_ABC'!$H$50*0.65 + '3_Strategic_Options_ABC'!$H$50*0.35*($A9/104927)))/10 -> 29.423048 | D9: ='3_Strategic_Options_ABC'!$E$50*(('3_Strategic_Options_ABC'!$G$50*(1+D$5))-('3_Strategic_Options_ABC'!$H$50*0.65 + '3_Strategic_Options_ABC'!$H$50*0.35*($A9/104927)))/10 -> 40.641586 | E9: ='3_Strategic_Options_ABC'!$E$50*(('3_Strategic_Options_ABC'!$G$50*(1+E$5))-('3_Strategic_Options_ABC'!$H$50*0.65 + '3_Strategic_Options_ABC'!$H$50*0.35*($A9/104927)))/10 -> 51.860124 | F9: ='3_Strategic_Options_ABC'!$E$50*(('3_Strategic_Options_ABC'!$G$50*(1+F$5))-('3_Strategic_Options_ABC'!$H$50*0.65 + '3_Strategic_Options_ABC'!$H$50*0.35*($A9/104927)))/10 -> 63.078661
A10: 125000 | B10: ='3_Strategic_Options_ABC'!$E$50*(('3_Strategic_Options_ABC'!$G$50*(1+B$5))-('3_Strategic_Options_ABC'!$H$50*0.65 + '3_Strategic_Options_ABC'!$H$50*0.35*($A10/104927)))/10 -> 7.4478811 | C10: ='3_Strategic_Options_ABC'!$E$50*(('3_Strategic_Options_ABC'!$G$50*(1+C$5))-('3_Strategic_Options_ABC'!$H$50*0.65 + '3_Strategic_Options_ABC'!$H$50*0.35*($A10/104927)))/10 -> 18.666419 | D10: ='3_Strategic_Options_ABC'!$E$50*(('3_Strategic_Options_ABC'!$G$50*(1+D$5))-('3_Strategic_Options_ABC'!$H$50*0.65 + '3_Strategic_Options_ABC'!$H$50*0.35*($A10/104927)))/10 -> 29.884957 | E10: ='3_Strategic_Options_ABC'!$E$50*(('3_Strategic_Options_ABC'!$G$50*(1+E$5))-('3_Strategic_Options_ABC'!$H$50*0.65 + '3_Strategic_Options_ABC'!$H$50*0.35*($A10/104927)))/10 -> 41.103495 | F10: ='3_Strategic_Options_ABC'!$E$50*(('3_Strategic_Options_ABC'!$G$50*(1+F$5))-('3_Strategic_Options_ABC'!$H$50*0.65 + '3_Strategic_Options_ABC'!$H$50*0.35*($A10/104927)))/10 -> 52.322032
A13: 2. MANDATORY STRESS SCENARIOS & QUANTIFIED MITIGATION MECHANISMS
A14: Risk Scenario Code | B14: Macro / Operational Trigger | C14: Unmitigated EBITDAR Impact (INR Cr) | D14: Specific Mitigation Mechanism | E14: Post-Mitigation EBITDAR (INR Cr) | F14: Residual BLF (%)
A15: Scenario 1: Severe Macro Fuel & FX Shock | B15: Brent Crude spikes to $105/bbl + INR depreciates to 89/USD -> ATF hits INR 1,22,000/kl (+16.3% above FY25 shock) | C15: ='3_Strategic_Options_ABC'!J50-24.8 -> 26.676738 | D15: Automatic Fuel Surcharge Indexation (INR 250/pax tier) + Tankering from 1% VAT UDAN spokes + 40% Crack-Spread Collar | E15: =C15+19.4 -> 46.076738 | F15: 0.785
A16: Scenario 2: UDAN VGF Receivables Delay & Sunset | B16: 180-day working-capital delay in State 20% VGF reimbursement + Year-3 VGF subsidy cliff on R4-R6 | C16: ='3_Strategic_Options_ABC'!J50-16.2 -> 35.276738 | D16: Escrow State BG Receivables Facility + Pre-negotiated 25% Commercial Seat Mix Shift as ATR 72-600 route matures | E16: =C16+13.5 -> 48.776738 | F16: 0.768
A17: Scenario 3: ATR 72-600 Wet-to-Dry Lease Delay | B17: 6-month OEM/lessor delivery delay on 4 ATR 72-600 turboprops due to Pratt & Whitney supply chain bottlenecks | C17: ='3_Strategic_Options_ABC'!J50-14.5 -> 36.976738 | D17: Interim Damp-Lease Bridge from regional lessor + Immediate Frequency Cap (1x daily) on R4-R6 until turboprop induction | E17: =C17+11.2 -> 48.176738 | F17: 0.774
